<?xml version="1.0" ?>
<robot name="wizzybug" xmlns:xacro="http://ros.org/wiki/xacro">
  <xacro:include filename="$(find wizzybug_description)/urdf/common_properties.xacro"/>
<!--  <xacro:include filename="$(find wizzybug_description)/urdf/wizzybug.gazebo"/>-->

  <link name="base_footprint"/>

  <joint name="base_joint" type="fixed">
    <parent link="base_footprint"/>
    <child link="base_link"/>
    <origin xyz="0.0 0.0 0.1025" rpy="0 0 0"/>
  </joint>

  <link name="base_link">
    <visual>
      <origin xyz="-0.09 -0.195 -0.05" rpy="0 0 0"/>
      <geometry>
				<mesh filename="package://wizzibug_description/meshes/Wizzibug_no_wheels.STL" scale="0.001 0.001 0.001"/>
      </geometry>
      <material name="red"/>
    </visual>

    <collision>
      <origin xyz="0 0 0" rpy="0 0 0"/>
      <geometry>
        <box size="1.0 1.0 1.0"/>
      </geometry>
    </collision>

    <inertial>
      <origin xyz="0 0 0" rpy="0 0 0"/>
      <mass value="30"/>
      <inertia ixx="1.0" ixy="0.0" ixz="0.0"
               iyy="1.0" iyz="0.0"
               izz="1.0" />
    </inertial>
  </link>


<!-- ################################Left Wheel##############################################-->
  <link name="wheel_left_link">
    <visual>
      <geometry>
        <cylinder length="0.06" radius="0.1025"/>
      </geometry>
      <origin rpy="1.5708 0 0" xyz="0 0 0"/>
      <material name="black"/>
    </visual>
    <collision>
      <geometry>
        <cylinder length="0.06" radius="0.1025"/>
      </geometry>
      <origin rpy="1.5708 0 0" xyz="0 0 0"/>
    </collision>
    <inertial>
      <mass value="1"/>
      <inertia ixx="1.0" ixy="0.0" ixz="0.0" iyy="1.0" iyz="0.0" izz="1.0"/>
    </inertial>
  </link>
  <joint name="wheel_left_joint" type="continuous">
    <parent link="base_link"/>
    <child link="wheel_left_link"/>
    <origin xyz="0.0 0.23 0.0" rpy="0 0 0"/>
    <axis xyz="0 1 0"/>
  </joint>

<!-- ################################Right Wheel##############################################-->
  <link name="wheel_right_link">
    <visual>
      <geometry>
        <cylinder length="0.06" radius="0.1025"/>
      </geometry>
      <origin rpy="1.5708 0 0" xyz="0 0 0"/>
      <material name="black"/>
    </visual>
    <collision>
      <geometry>
        <cylinder length="0.06" radius="0.1025"/>
      </geometry>
      <origin rpy="1.5708 0 0" xyz="0 0 0"/>
    </collision>
    <inertial>
      <mass value="${base_mass}"/>
      <inertia ixx="1.0"   iyy="1.0"  izz="1.0"/>
    </inertial>
  </link>

  <joint name="wheel_right_joint" type="continuous">
    <parent link="base_link"/>
    <child link="wheel_right_link"/>
    <origin xyz="0.0 -0.23 0.0" rpy="0 0 0"/>

  </joint>


  <joint name="imu_joint" type="fixed">
    <parent link="base_link"/>
    <child link="imu_link"/>
    <origin xyz="0.0 0 0.0" rpy="0 0 0"/>
  </joint>

  <link name="imu_link"/>



</robot>
